<?xml version="1.0"?>

<robot xmlns:xacro="http://ros.org/wiki/xacro">
  <xacro:macro name="drive_wheel_macro" params="robot_namespace parent prefix mass radius length xyz">
    <link name="${robot_namespace}/${prefix}_link">
      <visual>
        <origin xyz="0 0 0" rpy="0 0 0"/>
        <geometry>
          <cylinder radius="${radius}" length="${length}"/>
        </geometry>
        <material name="flat_black"/>
      </visual>

      <collision>
        <origin xyz="0 0 0" rpy="0 0 0"/>
        <geometry>
          <cylinder radius="${radius}" length="${length}"/>
        </geometry>
      </collision>

      <inertial>
        <origin xyz="0 0 0" rpy="0 0 0"/>
        <mass value="${mass}"/>
        <xacro:cylinder_inertia_macro mass="${mass}" radius="${radius}" length="${length}"/>
      </inertial>
    </link>

    <joint name="${robot_namespace}/${prefix}_joint" type="continuous">
      <origin xyz="${xyz}" rpy="${-rad90} 0 0"/>
      <parent link="${robot_namespace}/${parent}"/>
      <child link="${robot_namespace}/${prefix}_link"/>
      <axis xyz="0 0 1"/>
    </joint>
    
    <!-- Gazebo elements -->
    <gazebo reference="${robot_namespace}/${prefix}_link">
      <material>Gazebo/FlatBlack</material>
      <kp>5000000.0</kp>
      <kd>100.0</kd>
      <mu1>1.0</mu1>
      <mu2>1.0</mu2>
      <maxVel>1.0</maxVel>
      <minDepth>0.002</minDepth>
    </gazebo>
  </xacro:macro>
</robot>